Traceback (most recent call last):
  File "/opt/hostedtoolcache/Python/3.10.9/x64/lib/python3.10/site-packages/jupyter_cache/executors/utils.py", line 51, in single_nb_execution
    executenb(
  File "/opt/hostedtoolcache/Python/3.10.9/x64/lib/python3.10/site-packages/nbclient/client.py", line 1204, in execute
    return NotebookClient(nb=nb, resources=resources, km=km, **kwargs).execute()
  File "/opt/hostedtoolcache/Python/3.10.9/x64/lib/python3.10/site-packages/nbclient/util.py", line 84, in wrapped
    return just_run(coro(*args, **kwargs))
  File "/opt/hostedtoolcache/Python/3.10.9/x64/lib/python3.10/site-packages/nbclient/util.py", line 62, in just_run
    return loop.run_until_complete(coro)
  File "/opt/hostedtoolcache/Python/3.10.9/x64/lib/python3.10/asyncio/base_events.py", line 649, in run_until_complete
    return future.result()
  File "/opt/hostedtoolcache/Python/3.10.9/x64/lib/python3.10/site-packages/nbclient/client.py", line 663, in async_execute
    await self.async_execute_cell(
  File "/opt/hostedtoolcache/Python/3.10.9/x64/lib/python3.10/site-packages/nbclient/client.py", line 965, in async_execute_cell
    await self._check_raise_for_error(cell, cell_index, exec_reply)
  File "/opt/hostedtoolcache/Python/3.10.9/x64/lib/python3.10/site-packages/nbclient/client.py", line 862, in _check_raise_for_error
    raise CellExecutionError.from_cell_and_msg(cell, exec_reply_content)
nbclient.exceptions.CellExecutionError: An error occurred while executing the following cell:
------------------
# wait for the solve to complete
await waitForCompletion(navability_client, [solve_request], maxSeconds=180)

# click the generated graphic to link to the NavAbiltiy WebApp visualization
MapVizApp(client)
------------------

[0;31m---------------------------------------------------------------------------[0m
[0;31mTypeError[0m                                 Traceback (most recent call last)
Input [0;32mIn [9][0m, in [0;36m<cell line: 5>[0;34m()[0m
[1;32m      2[0m [38;5;28;01mawait[39;00m waitForCompletion(navability_client, [solve_request], maxSeconds[38;5;241m=[39m[38;5;241m180[39m)
[1;32m      4[0m [38;5;66;03m# click the generated graphic to link to the NavAbiltiy WebApp visualization[39;00m
[0;32m----> 5[0m [43mMapVizApp[49m[43m([49m[43mclient[49m[43m)[49m

File [0;32m/opt/hostedtoolcache/Python/3.10.9/x64/lib/python3.10/site-packages/navability/services/utils.py:62[0m, in [0;36mMapVizApp[0;34m(client, variableStartsWith)[0m
[1;32m     60[0m [38;5;28;01mif[39;00m variableStartsWith [38;5;129;01mis[39;00m [38;5;28;01mNone[39;00m:
[1;32m     61[0m     geometry_vis_link [38;5;241m=[39m geometry_vis_link [38;5;241m+[39m [38;5;124m"[39m[38;5;124m&variableStartsWith[39m[38;5;124m"[39m
[0;32m---> 62[0m     [38;5;28;01mif[39;00m [38;5;241m0[39m [38;5;241m<[39m [38;5;28;43mlen[39;49m[43m([49m[43mvariableStartsWith[49m[43m)[49m:
[1;32m     63[0m         geometry_vis_link [38;5;241m=[39m geometry_vis_link [38;5;241m+[39m [38;5;124m"[39m[38;5;124m=[39m[38;5;124m"[39m [38;5;241m+[39m variableStartsWith
[1;32m     64[0m [38;5;28mprint[39m(geometry_vis_link)

[0;31mTypeError[0m: object of type 'NoneType' has no len()
TypeError: object of type 'NoneType' has no len()

